[2021-09-29 17:44:04,798] {taskinstance.py:670} INFO - Dependencies all met for <TaskInstance: test-05.write_dw 2021-09-29T19:40:00+00:00 [queued]>
[2021-09-29 17:44:04,813] {taskinstance.py:670} INFO - Dependencies all met for <TaskInstance: test-05.write_dw 2021-09-29T19:40:00+00:00 [queued]>
[2021-09-29 17:44:04,813] {taskinstance.py:880} INFO - 
--------------------------------------------------------------------------------
[2021-09-29 17:44:04,813] {taskinstance.py:881} INFO - Starting attempt 1 of 2
[2021-09-29 17:44:04,813] {taskinstance.py:882} INFO - 
--------------------------------------------------------------------------------
[2021-09-29 17:44:04,905] {taskinstance.py:901} INFO - Executing <Task(PythonOperator): write_dw> on 2021-09-29T19:40:00+00:00
[2021-09-29 17:44:04,907] {standard_task_runner.py:54} INFO - Started process 3458 to run task
[2021-09-29 17:44:04,942] {standard_task_runner.py:77} INFO - Running: ['airflow', 'run', 'test-05', 'write_dw', '2021-09-29T19:40:00+00:00', '--job_id', '219', '--pool', 'default_pool', '--raw', '-sd', 'DAGS_FOLDER/test05.py', '--cfg_path', '/tmp/tmp8ga0zg5g']
[2021-09-29 17:44:04,943] {standard_task_runner.py:78} INFO - Job 219: Subtask write_dw
[2021-09-29 17:44:05,153] {logging_mixin.py:112} INFO - Running %s on host %s <TaskInstance: test-05.write_dw 2021-09-29T19:40:00+00:00 [running]> alunoigti-VirtualBox
[2021-09-29 17:44:05,776] {taskinstance.py:1150} ERROR - '_Environ' object is not callable
Traceback (most recent call last):
  File "/home/alunoigti/anaconda3/lib/python3.8/site-packages/airflow/models/taskinstance.py", line 984, in _run_raw_task
    result = task_copy.execute(context=context)
  File "/home/alunoigti/anaconda3/lib/python3.8/site-packages/airflow/operators/python_operator.py", line 113, in execute
    return_value = self.execute_callable()
  File "/home/alunoigti/anaconda3/lib/python3.8/site-packages/airflow/operators/python_operator.py", line 118, in execute_callable
    return self.python_callable(*self.op_args, **self.op_kwargs)
  File "/home/alunoigti/airflow/dags/test05.py", line 205, in write_to_dw
    user = os.environ('USERNAME_DB')
TypeError: '_Environ' object is not callable
[2021-09-29 17:44:05,777] {taskinstance.py:1187} INFO - Marking task as UP_FOR_RETRY. dag_id=test-05, task_id=write_dw, execution_date=20210929T194000, start_date=20210929T204404, end_date=20210929T204405
[2021-09-29 17:44:09,777] {local_task_job.py:102} INFO - Task exited with return code 1
