[2021-09-28 20:35:24,306] {taskinstance.py:670} INFO - Dependencies all met for <TaskInstance: test-02.compute-mean-age 2021-09-28T00:08:00+00:00 [queued]>
[2021-09-28 20:35:24,323] {taskinstance.py:670} INFO - Dependencies all met for <TaskInstance: test-02.compute-mean-age 2021-09-28T00:08:00+00:00 [queued]>
[2021-09-28 20:35:24,324] {taskinstance.py:880} INFO - 
--------------------------------------------------------------------------------
[2021-09-28 20:35:24,325] {taskinstance.py:881} INFO - Starting attempt 1 of 2
[2021-09-28 20:35:24,325] {taskinstance.py:882} INFO - 
--------------------------------------------------------------------------------
[2021-09-28 20:35:24,347] {taskinstance.py:901} INFO - Executing <Task(PythonOperator): compute-mean-age> on 2021-09-28T00:08:00+00:00
[2021-09-28 20:35:24,354] {standard_task_runner.py:54} INFO - Started process 4942 to run task
[2021-09-28 20:35:24,437] {standard_task_runner.py:77} INFO - Running: ['airflow', 'run', 'test-02', 'compute-mean-age', '2021-09-28T00:08:00+00:00', '--job_id', '29', '--pool', 'default_pool', '--raw', '-sd', 'DAGS_FOLDER/test02.py', '--cfg_path', '/tmp/tmp614iyl1n']
[2021-09-28 20:35:24,439] {standard_task_runner.py:78} INFO - Job 29: Subtask compute-mean-age
[2021-09-28 20:35:24,563] {logging_mixin.py:112} INFO - Running %s on host %s <TaskInstance: test-02.compute-mean-age 2021-09-28T00:08:00+00:00 [running]> alunoigti-VirtualBox
[2021-09-28 20:35:24,579] {taskinstance.py:1150} ERROR - 'task_instance'
Traceback (most recent call last):
  File "/home/alunoigti/anaconda3/lib/python3.8/site-packages/airflow/models/taskinstance.py", line 984, in _run_raw_task
    result = task_copy.execute(context=context)
  File "/home/alunoigti/anaconda3/lib/python3.8/site-packages/airflow/operators/python_operator.py", line 113, in execute
    return_value = self.execute_callable()
  File "/home/alunoigti/anaconda3/lib/python3.8/site-packages/airflow/operators/python_operator.py", line 118, in execute_callable
    return self.python_callable(*self.op_args, **self.op_kwargs)
  File "/home/alunoigti/airflow/dags/test02.py", line 64, in print_age
    value = context['task_instance'].xcom_pull(task_ids='compute-mean-age')
KeyError: 'task_instance'
[2021-09-28 20:35:24,580] {taskinstance.py:1187} INFO - Marking task as UP_FOR_RETRY. dag_id=test-02, task_id=compute-mean-age, execution_date=20210928T000800, start_date=20210928T233524, end_date=20210928T233524
[2021-09-28 20:35:29,291] {local_task_job.py:102} INFO - Task exited with return code 1
