[2021-09-28 20:38:10,392] {taskinstance.py:670} INFO - Dependencies all met for <TaskInstance: test-02.compute-mean-age 2021-09-28T00:08:00+00:00 [queued]>
[2021-09-28 20:38:10,406] {taskinstance.py:670} INFO - Dependencies all met for <TaskInstance: test-02.compute-mean-age 2021-09-28T00:08:00+00:00 [queued]>
[2021-09-28 20:38:10,407] {taskinstance.py:880} INFO - 
--------------------------------------------------------------------------------
[2021-09-28 20:38:10,408] {taskinstance.py:881} INFO - Starting attempt 2 of 2
[2021-09-28 20:38:10,408] {taskinstance.py:882} INFO - 
--------------------------------------------------------------------------------
[2021-09-28 20:38:10,506] {taskinstance.py:901} INFO - Executing <Task(PythonOperator): compute-mean-age> on 2021-09-28T00:08:00+00:00
[2021-09-28 20:38:10,531] {standard_task_runner.py:54} INFO - Started process 5259 to run task
[2021-09-28 20:38:10,626] {standard_task_runner.py:77} INFO - Running: ['airflow', 'run', 'test-02', 'compute-mean-age', '2021-09-28T00:08:00+00:00', '--job_id', '34', '--pool', 'default_pool', '--raw', '-sd', 'DAGS_FOLDER/test02.py', '--cfg_path', '/tmp/tmpksyt1tfo']
[2021-09-28 20:38:10,627] {standard_task_runner.py:78} INFO - Job 34: Subtask compute-mean-age
[2021-09-28 20:38:10,807] {logging_mixin.py:112} INFO - Running %s on host %s <TaskInstance: test-02.compute-mean-age 2021-09-28T00:08:00+00:00 [running]> alunoigti-VirtualBox
[2021-09-28 20:38:10,825] {taskinstance.py:1150} ERROR - 'task_instance'
Traceback (most recent call last):
  File "/home/alunoigti/anaconda3/lib/python3.8/site-packages/airflow/models/taskinstance.py", line 984, in _run_raw_task
    result = task_copy.execute(context=context)
  File "/home/alunoigti/anaconda3/lib/python3.8/site-packages/airflow/operators/python_operator.py", line 113, in execute
    return_value = self.execute_callable()
  File "/home/alunoigti/anaconda3/lib/python3.8/site-packages/airflow/operators/python_operator.py", line 118, in execute_callable
    return self.python_callable(*self.op_args, **self.op_kwargs)
  File "/home/alunoigti/airflow/dags/test02.py", line 64, in print_age
    value = context['task_instance'].xcom_pull(task_ids='compute-mean-age')
KeyError: 'task_instance'
[2021-09-28 20:38:10,827] {taskinstance.py:1187} INFO - Marking task as FAILED. dag_id=test-02, task_id=compute-mean-age, execution_date=20210928T000800, start_date=20210928T233810, end_date=20210928T233810
[2021-09-28 20:38:15,381] {local_task_job.py:102} INFO - Task exited with return code 1
