[2021-09-29 17:45:54,872] {taskinstance.py:670} INFO - Dependencies all met for <TaskInstance: test-05.write_dw 2021-09-29T19:50:00+00:00 [queued]>
[2021-09-29 17:45:54,891] {taskinstance.py:670} INFO - Dependencies all met for <TaskInstance: test-05.write_dw 2021-09-29T19:50:00+00:00 [queued]>
[2021-09-29 17:45:54,892] {taskinstance.py:880} INFO - 
--------------------------------------------------------------------------------
[2021-09-29 17:45:54,892] {taskinstance.py:881} INFO - Starting attempt 1 of 2
[2021-09-29 17:45:54,892] {taskinstance.py:882} INFO - 
--------------------------------------------------------------------------------
[2021-09-29 17:45:54,904] {taskinstance.py:901} INFO - Executing <Task(PythonOperator): write_dw> on 2021-09-29T19:50:00+00:00
[2021-09-29 17:45:54,905] {standard_task_runner.py:54} INFO - Started process 3590 to run task
[2021-09-29 17:45:54,939] {standard_task_runner.py:77} INFO - Running: ['airflow', 'run', 'test-05', 'write_dw', '2021-09-29T19:50:00+00:00', '--job_id', '225', '--pool', 'default_pool', '--raw', '-sd', 'DAGS_FOLDER/test05.py', '--cfg_path', '/tmp/tmp654pxmnt']
[2021-09-29 17:45:54,939] {standard_task_runner.py:78} INFO - Job 225: Subtask write_dw
[2021-09-29 17:45:55,030] {logging_mixin.py:112} INFO - Running %s on host %s <TaskInstance: test-05.write_dw 2021-09-29T19:50:00+00:00 [running]> alunoigti-VirtualBox
[2021-09-29 17:45:56,100] {taskinstance.py:1150} ERROR - (pyodbc.InterfaceError) ('28000', "[28000] [Microsoft][ODBC Driver 17 for SQL Server][SQL Server]Login failed for user 'None'. (18456) (SQLDriverConnect)")
(Background on this error at: http://sqlalche.me/e/13/rvf5)
Traceback (most recent call last):
  File "/home/alunoigti/anaconda3/lib/python3.8/site-packages/sqlalchemy/engine/base.py", line 2336, in _wrap_pool_connect
    return fn()
  File "/home/alunoigti/anaconda3/lib/python3.8/site-packages/sqlalchemy/pool/base.py", line 364, in connect
    return _ConnectionFairy._checkout(self)
  File "/home/alunoigti/anaconda3/lib/python3.8/site-packages/sqlalchemy/pool/base.py", line 778, in _checkout
    fairy = _ConnectionRecord.checkout(pool)
  File "/home/alunoigti/anaconda3/lib/python3.8/site-packages/sqlalchemy/pool/base.py", line 495, in checkout
    rec = pool._do_get()
  File "/home/alunoigti/anaconda3/lib/python3.8/site-packages/sqlalchemy/pool/impl.py", line 140, in _do_get
    self._dec_overflow()
  File "/home/alunoigti/anaconda3/lib/python3.8/site-packages/sqlalchemy/util/langhelpers.py", line 68, in __exit__
    compat.raise_(
  File "/home/alunoigti/anaconda3/lib/python3.8/site-packages/sqlalchemy/util/compat.py", line 182, in raise_
    raise exception
  File "/home/alunoigti/anaconda3/lib/python3.8/site-packages/sqlalchemy/pool/impl.py", line 137, in _do_get
    return self._create_connection()
  File "/home/alunoigti/anaconda3/lib/python3.8/site-packages/sqlalchemy/pool/base.py", line 309, in _create_connection
    return _ConnectionRecord(self)
  File "/home/alunoigti/anaconda3/lib/python3.8/site-packages/sqlalchemy/pool/base.py", line 440, in __init__
    self.__connect(first_connect_check=True)
  File "/home/alunoigti/anaconda3/lib/python3.8/site-packages/sqlalchemy/pool/base.py", line 661, in __connect
    pool.logger.debug("Error on connect(): %s", e)
  File "/home/alunoigti/anaconda3/lib/python3.8/site-packages/sqlalchemy/util/langhelpers.py", line 68, in __exit__
    compat.raise_(
  File "/home/alunoigti/anaconda3/lib/python3.8/site-packages/sqlalchemy/util/compat.py", line 182, in raise_
    raise exception
  File "/home/alunoigti/anaconda3/lib/python3.8/site-packages/sqlalchemy/pool/base.py", line 656, in __connect
    connection = pool._invoke_creator(self)
  File "/home/alunoigti/anaconda3/lib/python3.8/site-packages/sqlalchemy/engine/strategies.py", line 114, in connect
    return dialect.connect(*cargs, **cparams)
  File "/home/alunoigti/anaconda3/lib/python3.8/site-packages/sqlalchemy/engine/default.py", line 493, in connect
    return self.dbapi.connect(*cargs, **cparams)
pyodbc.InterfaceError: ('28000', "[28000] [Microsoft][ODBC Driver 17 for SQL Server][SQL Server]Login failed for user 'None'. (18456) (SQLDriverConnect)")

The above exception was the direct cause of the following exception:

Traceback (most recent call last):
  File "/home/alunoigti/anaconda3/lib/python3.8/site-packages/airflow/models/taskinstance.py", line 984, in _run_raw_task
    result = task_copy.execute(context=context)
  File "/home/alunoigti/anaconda3/lib/python3.8/site-packages/airflow/operators/python_operator.py", line 113, in execute
    return_value = self.execute_callable()
  File "/home/alunoigti/anaconda3/lib/python3.8/site-packages/airflow/operators/python_operator.py", line 118, in execute_callable
    return self.python_callable(*self.op_args, **self.op_kwargs)
  File "/home/alunoigti/airflow/dags/test05.py", line 210, in write_to_dw
    final.to_sql('enade_preprocessed', con=engine, index=False, if_exists='append')
  File "/home/alunoigti/anaconda3/lib/python3.8/site-packages/pandas/core/generic.py", line 2605, in to_sql
    sql.to_sql(
  File "/home/alunoigti/anaconda3/lib/python3.8/site-packages/pandas/io/sql.py", line 589, in to_sql
    pandas_sql.to_sql(
  File "/home/alunoigti/anaconda3/lib/python3.8/site-packages/pandas/io/sql.py", line 1393, in to_sql
    table.create()
  File "/home/alunoigti/anaconda3/lib/python3.8/site-packages/pandas/io/sql.py", line 721, in create
    if self.exists():
  File "/home/alunoigti/anaconda3/lib/python3.8/site-packages/pandas/io/sql.py", line 708, in exists
    return self.pd_sql.has_table(self.name, self.schema)
  File "/home/alunoigti/anaconda3/lib/python3.8/site-packages/pandas/io/sql.py", line 1430, in has_table
    return self.connectable.run_callable(
  File "/home/alunoigti/anaconda3/lib/python3.8/site-packages/sqlalchemy/engine/base.py", line 2211, in run_callable
    with self._contextual_connect() as conn:
  File "/home/alunoigti/anaconda3/lib/python3.8/site-packages/sqlalchemy/engine/base.py", line 2302, in _contextual_connect
    self._wrap_pool_connect(self.pool.connect, None),
  File "/home/alunoigti/anaconda3/lib/python3.8/site-packages/sqlalchemy/engine/base.py", line 2339, in _wrap_pool_connect
    Connection._handle_dbapi_exception_noconnection(
  File "/home/alunoigti/anaconda3/lib/python3.8/site-packages/sqlalchemy/engine/base.py", line 1583, in _handle_dbapi_exception_noconnection
    util.raise_(
  File "/home/alunoigti/anaconda3/lib/python3.8/site-packages/sqlalchemy/util/compat.py", line 182, in raise_
    raise exception
  File "/home/alunoigti/anaconda3/lib/python3.8/site-packages/sqlalchemy/engine/base.py", line 2336, in _wrap_pool_connect
    return fn()
  File "/home/alunoigti/anaconda3/lib/python3.8/site-packages/sqlalchemy/pool/base.py", line 364, in connect
    return _ConnectionFairy._checkout(self)
  File "/home/alunoigti/anaconda3/lib/python3.8/site-packages/sqlalchemy/pool/base.py", line 778, in _checkout
    fairy = _ConnectionRecord.checkout(pool)
  File "/home/alunoigti/anaconda3/lib/python3.8/site-packages/sqlalchemy/pool/base.py", line 495, in checkout
    rec = pool._do_get()
  File "/home/alunoigti/anaconda3/lib/python3.8/site-packages/sqlalchemy/pool/impl.py", line 140, in _do_get
    self._dec_overflow()
  File "/home/alunoigti/anaconda3/lib/python3.8/site-packages/sqlalchemy/util/langhelpers.py", line 68, in __exit__
    compat.raise_(
  File "/home/alunoigti/anaconda3/lib/python3.8/site-packages/sqlalchemy/util/compat.py", line 182, in raise_
    raise exception
  File "/home/alunoigti/anaconda3/lib/python3.8/site-packages/sqlalchemy/pool/impl.py", line 137, in _do_get
    return self._create_connection()
  File "/home/alunoigti/anaconda3/lib/python3.8/site-packages/sqlalchemy/pool/base.py", line 309, in _create_connection
    return _ConnectionRecord(self)
  File "/home/alunoigti/anaconda3/lib/python3.8/site-packages/sqlalchemy/pool/base.py", line 440, in __init__
    self.__connect(first_connect_check=True)
  File "/home/alunoigti/anaconda3/lib/python3.8/site-packages/sqlalchemy/pool/base.py", line 661, in __connect
    pool.logger.debug("Error on connect(): %s", e)
  File "/home/alunoigti/anaconda3/lib/python3.8/site-packages/sqlalchemy/util/langhelpers.py", line 68, in __exit__
    compat.raise_(
  File "/home/alunoigti/anaconda3/lib/python3.8/site-packages/sqlalchemy/util/compat.py", line 182, in raise_
    raise exception
  File "/home/alunoigti/anaconda3/lib/python3.8/site-packages/sqlalchemy/pool/base.py", line 656, in __connect
    connection = pool._invoke_creator(self)
  File "/home/alunoigti/anaconda3/lib/python3.8/site-packages/sqlalchemy/engine/strategies.py", line 114, in connect
    return dialect.connect(*cargs, **cparams)
  File "/home/alunoigti/anaconda3/lib/python3.8/site-packages/sqlalchemy/engine/default.py", line 493, in connect
    return self.dbapi.connect(*cargs, **cparams)
sqlalchemy.exc.InterfaceError: (pyodbc.InterfaceError) ('28000', "[28000] [Microsoft][ODBC Driver 17 for SQL Server][SQL Server]Login failed for user 'None'. (18456) (SQLDriverConnect)")
(Background on this error at: http://sqlalche.me/e/13/rvf5)
[2021-09-29 17:45:56,292] {taskinstance.py:1187} INFO - Marking task as UP_FOR_RETRY. dag_id=test-05, task_id=write_dw, execution_date=20210929T195000, start_date=20210929T204554, end_date=20210929T204556
[2021-09-29 17:45:59,861] {local_task_job.py:102} INFO - Task exited with return code 1
