[2021-09-29 17:16:35,797] {taskinstance.py:670} INFO - Dependencies all met for <TaskInstance: test-05.write_dw 2021-09-29T19:00:00+00:00 [queued]>
[2021-09-29 17:16:35,807] {taskinstance.py:670} INFO - Dependencies all met for <TaskInstance: test-05.write_dw 2021-09-29T19:00:00+00:00 [queued]>
[2021-09-29 17:16:35,808] {taskinstance.py:880} INFO - 
--------------------------------------------------------------------------------
[2021-09-29 17:16:35,808] {taskinstance.py:881} INFO - Starting attempt 2 of 2
[2021-09-29 17:16:35,808] {taskinstance.py:882} INFO - 
--------------------------------------------------------------------------------
[2021-09-29 17:16:35,818] {taskinstance.py:901} INFO - Executing <Task(PythonOperator): write_dw> on 2021-09-29T19:00:00+00:00
[2021-09-29 17:16:35,820] {standard_task_runner.py:54} INFO - Started process 54868 to run task
[2021-09-29 17:16:35,849] {standard_task_runner.py:77} INFO - Running: ['airflow', 'run', 'test-05', 'write_dw', '2021-09-29T19:00:00+00:00', '--job_id', '168', '--pool', 'default_pool', '--raw', '-sd', 'DAGS_FOLDER/test05.py', '--cfg_path', '/tmp/tmpuxg4ma1b']
[2021-09-29 17:16:35,849] {standard_task_runner.py:78} INFO - Job 168: Subtask write_dw
[2021-09-29 17:16:35,946] {logging_mixin.py:112} INFO - Running %s on host %s <TaskInstance: test-05.write_dw 2021-09-29T19:00:00+00:00 [running]> alunoigti-VirtualBox
[2021-09-29 17:16:36,371] {taskinstance.py:1150} ERROR - name 'os' is not defined
Traceback (most recent call last):
  File "/home/alunoigti/anaconda3/lib/python3.8/site-packages/airflow/models/taskinstance.py", line 984, in _run_raw_task
    result = task_copy.execute(context=context)
  File "/home/alunoigti/anaconda3/lib/python3.8/site-packages/airflow/operators/python_operator.py", line 113, in execute
    return_value = self.execute_callable()
  File "/home/alunoigti/anaconda3/lib/python3.8/site-packages/airflow/operators/python_operator.py", line 118, in execute_callable
    return self.python_callable(*self.op_args, **self.op_kwargs)
  File "/home/alunoigti/airflow/dags/test05.py", line 204, in write_to_dw
    user = os.environ('USERNAME_DB')
NameError: name 'os' is not defined
[2021-09-29 17:16:36,371] {taskinstance.py:1187} INFO - Marking task as FAILED. dag_id=test-05, task_id=write_dw, execution_date=20210929T190000, start_date=20210929T201635, end_date=20210929T201636
[2021-09-29 17:16:40,769] {local_task_job.py:102} INFO - Task exited with return code 1
