[2021-09-28 20:38:18,458] {taskinstance.py:670} INFO - Dependencies all met for <TaskInstance: test-02.compute-mean-age 2021-09-28T00:12:00+00:00 [queued]>
[2021-09-28 20:38:18,497] {taskinstance.py:670} INFO - Dependencies all met for <TaskInstance: test-02.compute-mean-age 2021-09-28T00:12:00+00:00 [queued]>
[2021-09-28 20:38:18,498] {taskinstance.py:880} INFO - 
--------------------------------------------------------------------------------
[2021-09-28 20:38:18,498] {taskinstance.py:881} INFO - Starting attempt 1 of 2
[2021-09-28 20:38:18,522] {taskinstance.py:882} INFO - 
--------------------------------------------------------------------------------
[2021-09-28 20:38:18,543] {taskinstance.py:901} INFO - Executing <Task(PythonOperator): compute-mean-age> on 2021-09-28T00:12:00+00:00
[2021-09-28 20:38:18,546] {standard_task_runner.py:54} INFO - Started process 5276 to run task
[2021-09-28 20:38:18,636] {standard_task_runner.py:77} INFO - Running: ['airflow', 'run', 'test-02', 'compute-mean-age', '2021-09-28T00:12:00+00:00', '--job_id', '35', '--pool', 'default_pool', '--raw', '-sd', 'DAGS_FOLDER/test02.py', '--cfg_path', '/tmp/tmpps4u_6e0']
[2021-09-28 20:38:18,639] {standard_task_runner.py:78} INFO - Job 35: Subtask compute-mean-age
[2021-09-28 20:38:18,817] {logging_mixin.py:112} INFO - Running %s on host %s <TaskInstance: test-02.compute-mean-age 2021-09-28T00:12:00+00:00 [running]> alunoigti-VirtualBox
[2021-09-28 20:38:18,843] {taskinstance.py:1150} ERROR - 'task_instance'
Traceback (most recent call last):
  File "/home/alunoigti/anaconda3/lib/python3.8/site-packages/airflow/models/taskinstance.py", line 984, in _run_raw_task
    result = task_copy.execute(context=context)
  File "/home/alunoigti/anaconda3/lib/python3.8/site-packages/airflow/operators/python_operator.py", line 113, in execute
    return_value = self.execute_callable()
  File "/home/alunoigti/anaconda3/lib/python3.8/site-packages/airflow/operators/python_operator.py", line 118, in execute_callable
    return self.python_callable(*self.op_args, **self.op_kwargs)
  File "/home/alunoigti/airflow/dags/test02.py", line 64, in print_age
    value = context['task_instance'].xcom_pull(task_ids='compute-mean-age')
KeyError: 'task_instance'
[2021-09-28 20:38:18,846] {taskinstance.py:1187} INFO - Marking task as UP_FOR_RETRY. dag_id=test-02, task_id=compute-mean-age, execution_date=20210928T001200, start_date=20210928T233818, end_date=20210928T233818
[2021-09-28 20:38:23,269] {local_task_job.py:102} INFO - Task exited with return code 1
