[2021-09-28 20:40:53,963] {taskinstance.py:670} INFO - Dependencies all met for <TaskInstance: test-02.compute-mean-age 2021-09-28T00:12:00+00:00 [queued]>
[2021-09-28 20:40:53,987] {taskinstance.py:670} INFO - Dependencies all met for <TaskInstance: test-02.compute-mean-age 2021-09-28T00:12:00+00:00 [queued]>
[2021-09-28 20:40:53,988] {taskinstance.py:880} INFO - 
--------------------------------------------------------------------------------
[2021-09-28 20:40:53,989] {taskinstance.py:881} INFO - Starting attempt 2 of 2
[2021-09-28 20:40:53,989] {taskinstance.py:882} INFO - 
--------------------------------------------------------------------------------
[2021-09-28 20:40:54,025] {taskinstance.py:901} INFO - Executing <Task(PythonOperator): compute-mean-age> on 2021-09-28T00:12:00+00:00
[2021-09-28 20:40:54,035] {standard_task_runner.py:54} INFO - Started process 5527 to run task
[2021-09-28 20:40:54,108] {standard_task_runner.py:77} INFO - Running: ['airflow', 'run', 'test-02', 'compute-mean-age', '2021-09-28T00:12:00+00:00', '--job_id', '41', '--pool', 'default_pool', '--raw', '-sd', 'DAGS_FOLDER/test02.py', '--cfg_path', '/tmp/tmptmu351rp']
[2021-09-28 20:40:54,110] {standard_task_runner.py:78} INFO - Job 41: Subtask compute-mean-age
[2021-09-28 20:40:54,253] {logging_mixin.py:112} INFO - Running %s on host %s <TaskInstance: test-02.compute-mean-age 2021-09-28T00:12:00+00:00 [running]> alunoigti-VirtualBox
[2021-09-28 20:40:54,279] {taskinstance.py:1150} ERROR - Error tokenizing data. C error: Expected 1 fields in line 111, saw 2
Traceback (most recent call last):
  File "/home/alunoigti/anaconda3/lib/python3.8/site-packages/airflow/models/taskinstance.py", line 984, in _run_raw_task
    result = task_copy.execute(context=context)
  File "/home/alunoigti/anaconda3/lib/python3.8/site-packages/airflow/operators/python_operator.py", line 113, in execute
    return_value = self.execute_callable()
  File "/home/alunoigti/anaconda3/lib/python3.8/site-packages/airflow/operators/python_operator.py", line 118, in execute_callable
    return self.python_callable(*self.op_args, **self.op_kwargs)
  File "/home/alunoigti/airflow/dags/test02.py", line 58, in compute_mean_age
    df = pd.read_csv('~/titanic.csv')
  File "/home/alunoigti/anaconda3/lib/python3.8/site-packages/pandas/io/parsers.py", line 686, in read_csv
    return _read(filepath_or_buffer, kwds)
  File "/home/alunoigti/anaconda3/lib/python3.8/site-packages/pandas/io/parsers.py", line 458, in _read
    data = parser.read(nrows)
  File "/home/alunoigti/anaconda3/lib/python3.8/site-packages/pandas/io/parsers.py", line 1196, in read
    ret = self._engine.read(nrows)
  File "/home/alunoigti/anaconda3/lib/python3.8/site-packages/pandas/io/parsers.py", line 2155, in read
    data = self._reader.read(nrows)
  File "pandas/_libs/parsers.pyx", line 847, in pandas._libs.parsers.TextReader.read
  File "pandas/_libs/parsers.pyx", line 862, in pandas._libs.parsers.TextReader._read_low_memory
  File "pandas/_libs/parsers.pyx", line 918, in pandas._libs.parsers.TextReader._read_rows
  File "pandas/_libs/parsers.pyx", line 905, in pandas._libs.parsers.TextReader._tokenize_rows
  File "pandas/_libs/parsers.pyx", line 2042, in pandas._libs.parsers.raise_parser_error
pandas.errors.ParserError: Error tokenizing data. C error: Expected 1 fields in line 111, saw 2

[2021-09-28 20:40:54,283] {taskinstance.py:1187} INFO - Marking task as FAILED. dag_id=test-02, task_id=compute-mean-age, execution_date=20210928T001200, start_date=20210928T234053, end_date=20210928T234054
[2021-09-28 20:40:58,912] {local_task_job.py:102} INFO - Task exited with return code 1
