[2021-09-28 20:36:38,068] {taskinstance.py:670} INFO - Dependencies all met for <TaskInstance: test-02.compute-mean-age 2021-09-28T00:06:00+00:00 [queued]>
[2021-09-28 20:36:38,097] {taskinstance.py:670} INFO - Dependencies all met for <TaskInstance: test-02.compute-mean-age 2021-09-28T00:06:00+00:00 [queued]>
[2021-09-28 20:36:38,099] {taskinstance.py:880} INFO - 
--------------------------------------------------------------------------------
[2021-09-28 20:36:38,099] {taskinstance.py:881} INFO - Starting attempt 2 of 2
[2021-09-28 20:36:38,099] {taskinstance.py:882} INFO - 
--------------------------------------------------------------------------------
[2021-09-28 20:36:38,151] {taskinstance.py:901} INFO - Executing <Task(PythonOperator): compute-mean-age> on 2021-09-28T00:06:00+00:00
[2021-09-28 20:36:38,154] {standard_task_runner.py:54} INFO - Started process 5100 to run task
[2021-09-28 20:36:38,262] {standard_task_runner.py:77} INFO - Running: ['airflow', 'run', 'test-02', 'compute-mean-age', '2021-09-28T00:06:00+00:00', '--job_id', '31', '--pool', 'default_pool', '--raw', '-sd', 'DAGS_FOLDER/test02.py', '--cfg_path', '/tmp/tmp60xy_3rt']
[2021-09-28 20:36:38,264] {standard_task_runner.py:78} INFO - Job 31: Subtask compute-mean-age
[2021-09-28 20:36:38,546] {logging_mixin.py:112} INFO - Running %s on host %s <TaskInstance: test-02.compute-mean-age 2021-09-28T00:06:00+00:00 [running]> alunoigti-VirtualBox
[2021-09-28 20:36:38,731] {taskinstance.py:1150} ERROR - 'task_instance'
Traceback (most recent call last):
  File "/home/alunoigti/anaconda3/lib/python3.8/site-packages/airflow/models/taskinstance.py", line 984, in _run_raw_task
    result = task_copy.execute(context=context)
  File "/home/alunoigti/anaconda3/lib/python3.8/site-packages/airflow/operators/python_operator.py", line 113, in execute
    return_value = self.execute_callable()
  File "/home/alunoigti/anaconda3/lib/python3.8/site-packages/airflow/operators/python_operator.py", line 118, in execute_callable
    return self.python_callable(*self.op_args, **self.op_kwargs)
  File "/home/alunoigti/airflow/dags/test02.py", line 64, in print_age
    value = context['task_instance'].xcom_pull(task_ids='compute-mean-age')
KeyError: 'task_instance'
[2021-09-28 20:36:38,752] {taskinstance.py:1187} INFO - Marking task as FAILED. dag_id=test-02, task_id=compute-mean-age, execution_date=20210928T000600, start_date=20210928T233638, end_date=20210928T233638
[2021-09-28 20:36:43,086] {local_task_job.py:102} INFO - Task exited with return code 1
