[2021-09-28 20:41:09,936] {taskinstance.py:670} INFO - Dependencies all met for <TaskInstance: test-02.compute-mean-age 2021-09-28T00:16:00+00:00 [queued]>
[2021-09-28 20:41:09,964] {taskinstance.py:670} INFO - Dependencies all met for <TaskInstance: test-02.compute-mean-age 2021-09-28T00:16:00+00:00 [queued]>
[2021-09-28 20:41:09,965] {taskinstance.py:880} INFO - 
--------------------------------------------------------------------------------
[2021-09-28 20:41:09,965] {taskinstance.py:881} INFO - Starting attempt 1 of 2
[2021-09-28 20:41:09,966] {taskinstance.py:882} INFO - 
--------------------------------------------------------------------------------
[2021-09-28 20:41:09,993] {taskinstance.py:901} INFO - Executing <Task(PythonOperator): compute-mean-age> on 2021-09-28T00:16:00+00:00
[2021-09-28 20:41:09,995] {standard_task_runner.py:54} INFO - Started process 5537 to run task
[2021-09-28 20:41:10,038] {standard_task_runner.py:77} INFO - Running: ['airflow', 'run', 'test-02', 'compute-mean-age', '2021-09-28T00:16:00+00:00', '--job_id', '43', '--pool', 'default_pool', '--raw', '-sd', 'DAGS_FOLDER/test02.py', '--cfg_path', '/tmp/tmp6mplcyit']
[2021-09-28 20:41:10,039] {standard_task_runner.py:78} INFO - Job 43: Subtask compute-mean-age
[2021-09-28 20:41:10,161] {logging_mixin.py:112} INFO - Running %s on host %s <TaskInstance: test-02.compute-mean-age 2021-09-28T00:16:00+00:00 [running]> alunoigti-VirtualBox
[2021-09-28 20:41:10,179] {taskinstance.py:1150} ERROR - Error tokenizing data. C error: Expected 1 fields in line 111, saw 2
Traceback (most recent call last):
  File "/home/alunoigti/anaconda3/lib/python3.8/site-packages/airflow/models/taskinstance.py", line 984, in _run_raw_task
    result = task_copy.execute(context=context)
  File "/home/alunoigti/anaconda3/lib/python3.8/site-packages/airflow/operators/python_operator.py", line 113, in execute
    return_value = self.execute_callable()
  File "/home/alunoigti/anaconda3/lib/python3.8/site-packages/airflow/operators/python_operator.py", line 118, in execute_callable
    return self.python_callable(*self.op_args, **self.op_kwargs)
  File "/home/alunoigti/airflow/dags/test02.py", line 58, in compute_mean_age
    df = pd.read_csv('~/titanic.csv')
  File "/home/alunoigti/anaconda3/lib/python3.8/site-packages/pandas/io/parsers.py", line 686, in read_csv
    return _read(filepath_or_buffer, kwds)
  File "/home/alunoigti/anaconda3/lib/python3.8/site-packages/pandas/io/parsers.py", line 458, in _read
    data = parser.read(nrows)
  File "/home/alunoigti/anaconda3/lib/python3.8/site-packages/pandas/io/parsers.py", line 1196, in read
    ret = self._engine.read(nrows)
  File "/home/alunoigti/anaconda3/lib/python3.8/site-packages/pandas/io/parsers.py", line 2155, in read
    data = self._reader.read(nrows)
  File "pandas/_libs/parsers.pyx", line 847, in pandas._libs.parsers.TextReader.read
  File "pandas/_libs/parsers.pyx", line 862, in pandas._libs.parsers.TextReader._read_low_memory
  File "pandas/_libs/parsers.pyx", line 918, in pandas._libs.parsers.TextReader._read_rows
  File "pandas/_libs/parsers.pyx", line 905, in pandas._libs.parsers.TextReader._tokenize_rows
  File "pandas/_libs/parsers.pyx", line 2042, in pandas._libs.parsers.raise_parser_error
pandas.errors.ParserError: Error tokenizing data. C error: Expected 1 fields in line 111, saw 2

[2021-09-28 20:41:10,181] {taskinstance.py:1187} INFO - Marking task as UP_FOR_RETRY. dag_id=test-02, task_id=compute-mean-age, execution_date=20210928T001600, start_date=20210928T234109, end_date=20210928T234110
[2021-09-28 20:41:14,851] {local_task_job.py:102} INFO - Task exited with return code 1
