[2021-09-28 20:36:53,063] {taskinstance.py:670} INFO - Dependencies all met for <TaskInstance: test-02.compute-mean-age 2021-09-28T00:10:00+00:00 [queued]>
[2021-09-28 20:36:53,088] {taskinstance.py:670} INFO - Dependencies all met for <TaskInstance: test-02.compute-mean-age 2021-09-28T00:10:00+00:00 [queued]>
[2021-09-28 20:36:53,094] {taskinstance.py:880} INFO - 
--------------------------------------------------------------------------------
[2021-09-28 20:36:53,095] {taskinstance.py:881} INFO - Starting attempt 1 of 2
[2021-09-28 20:36:53,095] {taskinstance.py:882} INFO - 
--------------------------------------------------------------------------------
[2021-09-28 20:36:53,169] {taskinstance.py:901} INFO - Executing <Task(PythonOperator): compute-mean-age> on 2021-09-28T00:10:00+00:00
[2021-09-28 20:36:53,171] {standard_task_runner.py:54} INFO - Started process 5119 to run task
[2021-09-28 20:36:53,266] {standard_task_runner.py:77} INFO - Running: ['airflow', 'run', 'test-02', 'compute-mean-age', '2021-09-28T00:10:00+00:00', '--job_id', '32', '--pool', 'default_pool', '--raw', '-sd', 'DAGS_FOLDER/test02.py', '--cfg_path', '/tmp/tmpmzi_3eru']
[2021-09-28 20:36:53,272] {standard_task_runner.py:78} INFO - Job 32: Subtask compute-mean-age
[2021-09-28 20:36:53,719] {logging_mixin.py:112} INFO - Running %s on host %s <TaskInstance: test-02.compute-mean-age 2021-09-28T00:10:00+00:00 [running]> alunoigti-VirtualBox
[2021-09-28 20:36:53,779] {taskinstance.py:1150} ERROR - 'task_instance'
Traceback (most recent call last):
  File "/home/alunoigti/anaconda3/lib/python3.8/site-packages/airflow/models/taskinstance.py", line 984, in _run_raw_task
    result = task_copy.execute(context=context)
  File "/home/alunoigti/anaconda3/lib/python3.8/site-packages/airflow/operators/python_operator.py", line 113, in execute
    return_value = self.execute_callable()
  File "/home/alunoigti/anaconda3/lib/python3.8/site-packages/airflow/operators/python_operator.py", line 118, in execute_callable
    return self.python_callable(*self.op_args, **self.op_kwargs)
  File "/home/alunoigti/airflow/dags/test02.py", line 64, in print_age
    value = context['task_instance'].xcom_pull(task_ids='compute-mean-age')
KeyError: 'task_instance'
[2021-09-28 20:36:53,785] {taskinstance.py:1187} INFO - Marking task as UP_FOR_RETRY. dag_id=test-02, task_id=compute-mean-age, execution_date=20210928T001000, start_date=20210928T233653, end_date=20210928T233653
[2021-09-28 20:36:57,951] {local_task_job.py:102} INFO - Task exited with return code 1
