[2021-09-28 20:35:15,778] {taskinstance.py:670} INFO - Dependencies all met for <TaskInstance: test-02.compute-mean-age 2021-09-28T23:31:30.714137+00:00 [queued]>
[2021-09-28 20:35:15,810] {taskinstance.py:670} INFO - Dependencies all met for <TaskInstance: test-02.compute-mean-age 2021-09-28T23:31:30.714137+00:00 [queued]>
[2021-09-28 20:35:15,811] {taskinstance.py:880} INFO - 
--------------------------------------------------------------------------------
[2021-09-28 20:35:15,812] {taskinstance.py:881} INFO - Starting attempt 2 of 2
[2021-09-28 20:35:15,812] {taskinstance.py:882} INFO - 
--------------------------------------------------------------------------------
[2021-09-28 20:35:15,835] {taskinstance.py:901} INFO - Executing <Task(PythonOperator): compute-mean-age> on 2021-09-28T23:31:30.714137+00:00
[2021-09-28 20:35:15,838] {standard_task_runner.py:54} INFO - Started process 4924 to run task
[2021-09-28 20:35:15,906] {standard_task_runner.py:77} INFO - Running: ['airflow', 'run', 'test-02', 'compute-mean-age', '2021-09-28T23:31:30.714137+00:00', '--job_id', '28', '--pool', 'default_pool', '--raw', '-sd', 'DAGS_FOLDER/test02.py', '--cfg_path', '/tmp/tmpbo9egi75']
[2021-09-28 20:35:15,911] {standard_task_runner.py:78} INFO - Job 28: Subtask compute-mean-age
[2021-09-28 20:35:16,196] {logging_mixin.py:112} INFO - Running %s on host %s <TaskInstance: test-02.compute-mean-age 2021-09-28T23:31:30.714137+00:00 [running]> alunoigti-VirtualBox
[2021-09-28 20:35:16,217] {taskinstance.py:1150} ERROR - 'task_instance'
Traceback (most recent call last):
  File "/home/alunoigti/anaconda3/lib/python3.8/site-packages/airflow/models/taskinstance.py", line 984, in _run_raw_task
    result = task_copy.execute(context=context)
  File "/home/alunoigti/anaconda3/lib/python3.8/site-packages/airflow/operators/python_operator.py", line 113, in execute
    return_value = self.execute_callable()
  File "/home/alunoigti/anaconda3/lib/python3.8/site-packages/airflow/operators/python_operator.py", line 118, in execute_callable
    return self.python_callable(*self.op_args, **self.op_kwargs)
  File "/home/alunoigti/airflow/dags/test02.py", line 64, in print_age
    value = context['task_instance'].xcom_pull(task_ids='compute-mean-age')
KeyError: 'task_instance'
[2021-09-28 20:35:16,219] {taskinstance.py:1187} INFO - Marking task as FAILED. dag_id=test-02, task_id=compute-mean-age, execution_date=20210928T233130, start_date=20210928T233515, end_date=20210928T233516
[2021-09-28 20:35:20,723] {local_task_job.py:102} INFO - Task exited with return code 1
